{"uuid": "018e8235-6c5c-4ecb-9a77-61b3ca927e44", "children": ["4907fa98-e75f-4444-873d-1e613e7071b9"], "befores": [{"name": "init_cart", "status": "passed", "start": 1605869264095, "stop": 1605869264095}], "afters": [{"name": "init_cart::0", "status": "broken", "statusDetails": {"message": "urllib3.exceptions.MaxRetryError: HTTPConnectionPool(host='127.0.0.1', port=12711): Max retries exceeded with url: /session/76e48b797145c84045a09a6d47198ab8/cookie (Caused by NewConnectionError('<urllib3.connection.HTTPConnection object at 0x047B6D30>: Failed to establish a new connection: [WinError 10061] 由于目标计算机积极拒绝，无法连接。'))\n", "trace": "  File \"D:\\python\\lib\\site-packages\\allure_commons\\_allure.py\", line 185, in __call__\n    return self._fixture_function(*args, **kwargs)\n  File \"D:\\python\\lib\\site-packages\\_pytest\\fixtures.py\", line 800, in _teardown_yield_fixture\n    next(it)\n  File \"D:\\pyProject\\PrimarySelenium\\case\\shoppingcart\\conftest.py\", line 25, in init_cart\n    init_driver.get_cookies()\n  File \"D:\\pyProject\\PrimarySelenium\\base\\basepage.py\", line 414, in get_cookies\n    cookie = self.driver.get_cookies()\n  File \"D:\\python\\lib\\site-packages\\selenium\\webdriver\\remote\\webdriver.py\", line 841, in get_cookies\n    return self.execute(Command.GET_ALL_COOKIES)['value']\n  File \"D:\\python\\lib\\site-packages\\selenium\\webdriver\\remote\\webdriver.py\", line 319, in execute\n    response = self.command_executor.execute(driver_command, params)\n  File \"D:\\python\\lib\\site-packages\\selenium\\webdriver\\remote\\remote_connection.py\", line 374, in execute\n    return self._request(command_info[0], url, body=data)\n  File \"D:\\python\\lib\\site-packages\\selenium\\webdriver\\remote\\remote_connection.py\", line 397, in _request\n    resp = self._conn.request(method, url, body=body, headers=headers)\n  File \"D:\\python\\lib\\site-packages\\urllib3\\request.py\", line 66, in request\n    return self.request_encode_url(method, url, fields=fields,\n  File \"D:\\python\\lib\\site-packages\\urllib3\\request.py\", line 89, in request_encode_url\n    return self.urlopen(method, url, **extra_kw)\n  File \"D:\\python\\lib\\site-packages\\urllib3\\poolmanager.py\", line 323, in urlopen\n    response = conn.urlopen(method, u.request_uri, **kw)\n  File \"D:\\python\\lib\\site-packages\\urllib3\\connectionpool.py\", line 663, in urlopen\n    return self.urlopen(method, url, body, headers, retries,\n  File \"D:\\python\\lib\\site-packages\\urllib3\\connectionpool.py\", line 663, in urlopen\n    return self.urlopen(method, url, body, headers, retries,\n  File \"D:\\python\\lib\\site-packages\\urllib3\\connectionpool.py\", line 663, in urlopen\n    return self.urlopen(method, url, body, headers, retries,\n  File \"D:\\python\\lib\\site-packages\\urllib3\\connectionpool.py\", line 637, in urlopen\n    retries = retries.increment(method, url, error=e, _pool=self,\n  File \"D:\\python\\lib\\site-packages\\urllib3\\util\\retry.py\", line 398, in increment\n    raise MaxRetryError(_pool, url, error or ResponseError(cause))\n"}, "start": 1605869298857, "stop": 1605869302887}], "start": 1605869264095, "stop": 1605869302887}